Workbook

Sheet 渠道优先级
A1: 渠道优先级
A2: 按“对外模型名 + 环境”配置顺位；1 最优先。只影响新会话的渠道选择。
A3: 浅黄色单元格可编辑；“本地检查”仅检查表内填写，正式生效仍需系统验证与发布。
A5: 对外模型名 | B5: 环境 | C5: 渠道名称 | D5: 渠道侧模型名 | E5: 顺位 | F5: 启用意向 | G5: 不可用时 | H5: 说明 | I5: 本地检查
A6: gemini-3.6-flash | B6: 测试 | C6: AIHubMix Gemini | D6: gemini-3.6-flash | E6: 1 | F6: 停用 | G6: 尝试下一顺位 | H6: 现有 Gemini 连接；该新模型待验证 | I6: =IF(A6="","",IF(COUNTIF('模型清单'!$B$6:$B$105,A6)=0,"模型未登记",IF(OR(B6="",C6="",D6="",E6="",F6="",G6=""),"信息不完整",IF(COUNTIFS($A$6:$A$105,A6,$B$6:$B$105,B6,$E$6:$E$105,E6)>1,"顺位重复",IF(COUNTIFS($A$6:$A$105,A6,$B$6:$B$105,B6,$C$6:$C$105,C6)>1,"渠道重复","待系统验证"))))) -> 待系统验证
A7: gemini-3.6-flash | B7: 测试 | C7: Google 官方（规划） | D7: gemini-3.6-flash | E7: 2 | F7: 停用 | G7: 拒绝新会话 | H7: 仅演示备用顺位；该渠道尚未接入 | I7: =IF(A7="","",IF(COUNTIF('模型清单'!$B$6:$B$105,A7)=0,"模型未登记",IF(OR(B7="",C7="",D7="",E7="",F7="",G7=""),"信息不完整",IF(COUNTIFS($A$6:$A$105,A7,$B$6:$B$105,B7,$E$6:$E$105,E7)>1,"顺位重复",IF(COUNTIFS($A$6:$A$105,A7,$B$6:$B$105,B7,$C$6:$C$105,C7)>1,"渠道重复","待系统验证"))))) -> 待系统验证
A8: gemini-4-argon | B8: 测试 | C8: AIHubMix Gemini | D8: gemini-4-argon | E8: 1 | F8: 停用 | G8: 尝试下一顺位 | H8: 隐式缓存投影与渠道验证尚未完成 | I8: =IF(A8="","",IF(COUNTIF('模型清单'!$B$6:$B$105,A8)=0,"模型未登记",IF(OR(B8="",C8="",D8="",E8="",F8="",G8=""),"信息不完整",IF(COUNTIFS($A$6:$A$105,A8,$B$6:$B$105,B8,$E$6:$E$105,E8)>1,"顺位重复",IF(COUNTIFS($A$6:$A$105,A8,$B$6:$B$105,B8,$C$6:$C$105,C8)>1,"渠道重复","待系统验证"))))) -> 待系统验证
A9: gemini-4-argon | B9: 测试 | C9: Google 官方（规划） | D9: gemini-4-argon | E9: 2 | F9: 停用 | G9: 拒绝新会话 | H9: 仅演示备用顺位；该渠道尚未接入 | I9: =IF(A9="","",IF(COUNTIF('模型清单'!$B$6:$B$105,A9)=0,"模型未登记",IF(OR(B9="",C9="",D9="",E9="",F9="",G9=""),"信息不完整",IF(COUNTIFS($A$6:$A$105,A9,$B$6:$B$105,B9,$E$6:$E$105,E9)>1,"顺位重复",IF(COUNTIFS($A$6:$A$105,A9,$B$6:$B$105,B9,$C$6:$C$105,C9)>1,"渠道重复","待系统验证"))))) -> 待系统验证
A10: gpt-6-astra | B10: 测试 | C10: OpenAI 官方（规划） | D10: gpt-6-astra | E10: 1 | F10: 停用 | G10: 尝试下一顺位 | H10: 仅候选，渠道未登记/未认证；不可仅凭模型列表启用。 | I10: =IF(A10="","",IF(COUNTIF('模型清单'!$B$6:$B$105,A10)=0,"模型未登记",IF(OR(B10="",C10="",D10="",E10="",F10="",G10=""),"信息不完整",IF(COUNTIFS($A$6:$A$105,A10,$B$6:$B$105,B10,$E$6:$E$105,E10)>1,"顺位重复",IF(COUNTIFS($A$6:$A$105,A10,$B$6:$B$105,B10,$C$6:$C$105,C10)>1,"渠道重复","待系统验证"))))) -> 待系统验证
A11: gpt-6-sol | B11: 测试 | C11: OpenAI 官方（规划） | D11: gpt-6-sol | E11: 1 | F11: 停用 | G11: 尝试下一顺位 | H11: 仅候选，渠道未登记/未认证；不可仅凭模型列表启用。 | I11: =IF(A11="","",IF(COUNTIF('模型清单'!$B$6:$B$105,A11)=0,"模型未登记",IF(OR(B11="",C11="",D11="",E11="",F11="",G11=""),"信息不完整",IF(COUNTIFS($A$6:$A$105,A11,$B$6:$B$105,B11,$E$6:$E$105,E11)>1,"顺位重复",IF(COUNTIFS($A$6:$A$105,A11,$B$6:$B$105,B11,$C$6:$C$105,C11)>1,"渠道重复","待系统验证"))))) -> 待系统验证
A12: gpt-6-luna | B12: 测试 | C12: OpenAI 官方（规划） | D12: gpt-6-luna | E12: 1 | F12: 停用 | G12: 尝试下一顺位 | H12: 仅候选，渠道未登记/未认证；不可仅凭模型列表启用。 | I12: =IF(A12="","",IF(COUNTIF('模型清单'!$B$6:$B$105,A12)=0,"模型未登记",IF(OR(B12="",C12="",D12="",E12="",F12="",G12=""),"信息不完整",IF(COUNTIFS($A$6:$A$105,A12,$B$6:$B$105,B12,$E$6:$E$105,E12)>1,"顺位重复",IF(COUNTIFS($A$6:$A$105,A12,$B$6:$B$105,B12,$C$6:$C$105,C12)>1,"渠道重复","待系统验证"))))) -> 待系统验证
A13: gpt-6.1-terra | B13: 测试 | C13: OpenAI 官方（规划） | D13: gpt-6.1-terra | E13: 1 | F13: 停用 | G13: 尝试下一顺位 | H13: 仅候选，渠道未登记/未认证；不可仅凭模型列表启用。 | I13: =IF(A13="","",IF(COUNTIF('模型清单'!$B$6:$B$105,A13)=0,"模型未登记",IF(OR(B13="",C13="",D13="",E13="",F13="",G13=""),"信息不完整",IF(COUNTIFS($A$6:$A$105,A13,$B$6:$B$105,B13,$E$6:$E$105,E13)>1,"顺位重复",IF(COUNTIFS($A$6:$A$105,A13,$B$6:$B$105,B13,$C$6:$C$105,C13)>1,"渠道重复","待系统验证"))))) -> 待系统验证
A14: gpt-5.5 | B14: 测试 | C14: OpenAI 官方（规划） | D14: gpt-5.5 | E14: 1 | F14: 停用 | G14: 尝试下一顺位 | H14: 仅候选，渠道未登记/未认证；API 模型仍应核对实际账户可用性 | I14: =IF(A14="","",IF(COUNTIF('模型清单'!$B$6:$B$105,A14)=0,"模型未登记",IF(OR(B14="",C14="",D14="",E14="",F14="",G14=""),"信息不完整",IF(COUNTIFS($A$6:$A$105,A14,$B$6:$B$105,B14,$E$6:$E$105,E14)>1,"顺位重复",IF(COUNTIFS($A$6:$A$105,A14,$B$6:$B$105,B14,$C$6:$C$105,C14)>1,"渠道重复","待系统验证"))))) -> 待系统验证
A15: claude-fable-5-1 | B15: 测试 | C15: Anthropic 官方（规划） | D15: claude-fable-5-1 | E15: 1 | F15: 停用 | G15: 尝试下一顺位 | H15: 仅候选，渠道未登记/未认证；不可仅凭模型列表启用。 | I15: =IF(A15="","",IF(COUNTIF('模型清单'!$B$6:$B$105,A15)=0,"模型未登记",IF(OR(B15="",C15="",D15="",E15="",F15="",G15=""),"信息不完整",IF(COUNTIFS($A$6:$A$105,A15,$B$6:$B$105,B15,$E$6:$E$105,E15)>1,"顺位重复",IF(COUNTIFS($A$6:$A$105,A15,$B$6:$B$105,B15,$C$6:$C$105,C15)>1,"渠道重复","待系统验证"))))) -> 待系统验证
A16: claude-opus-5-5 | B16: 测试 | C16: Anthropic 官方（规划） | D16: claude-opus-5-5 | E16: 1 | F16: 停用 | G16: 尝试下一顺位 | H16: 仅候选，渠道未登记/未认证；不可仅凭模型列表启用。 | I16: =IF(A16="","",IF(COUNTIF('模型清单'!$B$6:$B$105,A16)=0,"模型未登记",IF(OR(B16="",C16="",D16="",E16="",F16="",G16=""),"信息不完整",IF(COUNTIFS($A$6:$A$105,A16,$B$6:$B$105,B16,$E$6:$E$105,E16)>1,"顺位重复",IF(COUNTIFS($A$6:$A$105,A16,$B$6:$B$105,B16,$C$6:$C$105,C16)>1,"渠道重复","待系统验证"))))) -> 待系统验证
A17: claude-sonnet-5-5 | B17: 测试 | C17: Anthropic 官方（规划） | D17: claude-sonnet-5-5 | E17: 1 | F17: 停用 | G17: 尝试下一顺位 | H17: 仅候选，渠道未登记/未认证；不可仅凭模型列表启用。 | I17: =IF(A17="","",IF(COUNTIF('模型清单'!$B$6:$B$105,A17)=0,"模型未登记",IF(OR(B17="",C17="",D17="",E17="",F17="",G17=""),"信息不完整",IF(COUNTIFS($A$6:$A$105,A17,$B$6:$B$105,B17,$E$6:$E$105,E17)>1,"顺位重复",IF(COUNTIFS($A$6:$A$105,A17,$B$6:$B$105,B17,$C$6:$C$105,C17)>1,"渠道重复","待系统验证"))))) -> 待系统验证
... A66: glm-5.3-flash | B66: 测试 | C66: 智谱官方（规划） | D66: glm-5.3-flash | E66: 1 | F66: 停用 | G66: 尝试下一顺位 | H66: 额外补漏：GLM 官方 Flash 型号；与 coding-glm-5.3-free 为不同 ID；需要独立渠道认证 | I66: =IF(A66="","",IF(COUNTIF('模型清单'!$B$6:$B$105,A66)=0,"模型未登记",IF(OR(B66="",C66="",D66="",E66="",F66="",G66=""),"信息不完整",IF(COUNTIFS($A$6:$A$105,A66,$B$6:$B$105,B66,$E$6:$E$105,E66)>1,"顺位重复",IF(COUNTIFS($A$6:$A$105,A66,$B$6:$B$105,B66,$C$6:$C$105,C66)>1,"渠道重复","待系统验证"))))) -> 待系统验证
I67: =IF(A67="","",IF(COUNTIF('模型清单'!$B$6:$B$105,A67)=0,"模型未登记",IF(OR(B67="",C67="",D67="",E67="",F67="",G67=""),"信息不完整",IF(COUNTIFS($A$6:$A$105,A67,$B$6:$B$105,B67,$E$6:$E$105,E67)>1,"顺位重复",IF(COUNTIFS($A$6:$A$105,A67,$B$6:$B$105,B67,$C$6:$C$105,C67)>1,"渠道重复","待系统验证")))))
I68: =IF(A68="","",IF(COUNTIF('模型清单'!$B$6:$B$105,A68)=0,"模型未登记",IF(OR(B68="",C68="",D68="",E68="",F68="",G68=""),"信息不完整",IF(COUNTIFS($A$6:$A$105,A68,$B$6:$B$105,B68,$E$6:$E$105,E68)>1,"顺位重复",IF(COUNTIFS($A$6:$A$105,A68,$B$6:$B$105,B68,$C$6:$C$105,C68)>1,"渠道重复","待系统验证")))))
I69: =IF(A69="","",IF(COUNTIF('模型清单'!$B$6:$B$105,A69)=0,"模型未登记",IF(OR(B69="",C69="",D69="",E69="",F69="",G69=""),"信息不完整",IF(COUNTIFS($A$6:$A$105,A69,$B$6:$B$105,B69,$E$6:$E$105,E69)>1,"顺位重复",IF(COUNTIFS($A$6:$A$105,A69,$B$6:$B$105,B69,$C$6:$C$105,C69)>1,"渠道重复","待系统验证")))))
I70: =IF(A70="","",IF(COUNTIF('模型清单'!$B$6:$B$105,A70)=0,"模型未登记",IF(OR(B70="",C70="",D70="",E70="",F70="",G70=""),"信息不完整",IF(COUNTIFS($A$6:$A$105,A70,$B$6:$B$105,B70,$E$6:$E$105,E70)>1,"顺位重复",IF(COUNTIFS($A$6:$A$105,A70,$B$6:$B$105,B70,$C$6:$C$105,C70)>1,"渠道重复","待系统验证")))))
I71: =IF(A71="","",IF(COUNTIF('模型清单'!$B$6:$B$105,A71)=0,"模型未登记",IF(OR(B71="",C71="",D71="",E71="",F71="",G71=""),"信息不完整",IF(COUNTIFS($A$6:$A$105,A71,$B$6:$B$105,B71,$E$6:$E$105,E71)>1,"顺位重复",IF(COUNTIFS($A$6:$A$105,A71,$B$6:$B$105,B71,$C$6:$C$105,C71)>1,"渠道重复","待系统验证")))))
I72: =IF(A72="","",IF(COUNTIF('模型清单'!$B$6:$B$105,A72)=0,"模型未登记",IF(OR(B72="",C72="",D72="",E72="",F72="",G72=""),"信息不完整",IF(COUNTIFS($A$6:$A$105,A72,$B$6:$B$105,B72,$E$6:$E$105,E72)>1,"顺位重复",IF(COUNTIFS($A$6:$A$105,A72,$B$6:$B$105,B72,$C$6:$C$105,C72)>1,"渠道重复","待系统验证")))))
I73: =IF(A73="","",IF(COUNTIF('模型清单'!$B$6:$B$105,A73)=0,"模型未登记",IF(OR(B73="",C73="",D73="",E73="",F73="",G73=""),"信息不完整",IF(COUNTIFS($A$6:$A$105,A73,$B$6:$B$105,B73,$E$6:$E$105,E73)>1,"顺位重复",IF(COUNTIFS($A$6:$A$105,A73,$B$6:$B$105,B73,$C$6:$C$105,C73)>1,"渠道重复","待系统验证")))))
I74: =IF(A74="","",IF(COUNTIF('模型清单'!$B$6:$B$105,A74)=0,"模型未登记",IF(OR(B74="",C74="",D74="",E74="",F74="",G74=""),"信息不完整",IF(COUNTIFS($A$6:$A$105,A74,$B$6:$B$105,B74,$E$6:$E$105,E74)>1,"顺位重复",IF(COUNTIFS($A$6:$A$105,A74,$B$6:$B$105,B74,$C$6:$C$105,C74)>1,"渠道重复","待系统验证")))))
I75: =IF(A75="","",IF(COUNTIF('模型清单'!$B$6:$B$105,A75)=0,"模型未登记",IF(OR(B75="",C75="",D75="",E75="",F75="",G75=""),"信息不完整",IF(COUNTIFS($A$6:$A$105,A75,$B$6:$B$105,B75,$E$6:$E$105,E75)>1,"顺位重复",IF(COUNTIFS($A$6:$A$105,A75,$B$6:$B$105,B75,$C$6:$C$105,C75)>1,"渠道重复","待系统验证")))))
I76: =IF(A76="","",IF(COUNTIF('模型清单'!$B$6:$B$105,A76)=0,"模型未登记",IF(OR(B76="",C76="",D76="",E76="",F76="",G76=""),"信息不完整",IF(COUNTIFS($A$6:$A$105,A76,$B$6:$B$105,B76,$E$6:$E$105,E76)>1,"顺位重复",IF(COUNTIFS($A$6:$A$105,A76,$B$6:$B$105,B76,$C$6:$C$105,C76)>1,"渠道重复","待系统验证")))))
I77: =IF(A77="","",IF(COUNTIF('模型清单'!$B$6:$B$105,A77)=0,"模型未登记",IF(OR(B77="",C77="",D77="",E77="",F77="",G77=""),"信息不完整",IF(COUNTIFS($A$6:$A$105,A77,$B$6:$B$105,B77,$E$6:$E$105,E77)>1,"顺位重复",IF(COUNTIFS($A$6:$A$105,A77,$B$6:$B$105,B77,$C$6:$C$105,C77)>1,"渠道重复","待系统验证")))))
I78: =IF(A78="","",IF(COUNTIF('模型清单'!$B$6:$B$105,A78)=0,"模型未登记",IF(OR(B78="",C78="",D78="",E78="",F78="",G78=""),"信息不完整",IF(COUNTIFS($A$6:$A$105,A78,$B$6:$B$105,B78,$E$6:$E$105,E78)>1,"顺位重复",IF(COUNTIFS($A$6:$A$105,A78,$B$6:$B$105,B78,$C$6:$C$105,C78)>1,"渠道重复","待系统验证")))))
... I105: =IF(A105="","",IF(COUNTIF('模型清单'!$B$6:$B$105,A105)=0,"模型未登记",IF(OR(B105="",C105="",D105="",E105="",F105="",G105=""),"信息不完整",IF(COUNTIFS($A$6:$A$105,A105,$B$6:$B$105,B105,$E$6:$E$105,E105)>1,"顺位重复",IF(COUNTIFS($A$6:$A$105,A105,$B$6:$B$105,B105,$C$6:$C$105,C105)>1,"渠道重复","待系统验证")))))

Sheet 模型清单
A1: 模型清单
A2: 一个对外模型名只登记一次；模型能力为目标配置，须逐渠道核验。
A3: 浅黄色单元格可编辑；“本地检查”仅检查表内填写，正式生效仍需系统验证与发布。
A5: 显示名称 | B5: 对外模型名 | C5: 提供方 | D5: 输入类型 | E5: 思考档位 | F5: 结构化输出 | G5: 目标输出上限 Token | H5: 发布意向 | I5: 本地检查
A6: Gemini 3.6 Flash | B6: gemini-3.6-flash | C6: Gemini | D6: 文本、图片、文件 | E6: 自动、低、中、高 | F6: 原生 JSON Schema | G6: 65536 | H6: 暂不发布 | I6: =IF(B6="","",IF(COUNTIF($B$6:$B$105,B6)>1,"模型重复",IF(OR(A6="",C6="",D6="",H6=""),"信息不完整","待系统验证"))) -> 待系统验证
A7: Gemini 4 Argon | B7: gemini-4-argon | C7: Gemini | D7: 文本、图片、文件 | E7: 低、中、高 | F7: 原生 JSON Schema | G7: 32768 | H7: 暂不发布 | I7: =IF(B7="","",IF(COUNTIF($B$6:$B$105,B7)>1,"模型重复",IF(OR(A7="",C7="",D7="",H7=""),"信息不完整","待系统验证"))) -> 待系统验证
A8: GPT-6 Astra | B8: gpt-6-astra | C8: OpenAI | D8: 文本、图片 | E8: 自动 | F8: 后校验 | G8: 16384 | H8: 暂不发布 | I8: =IF(B8="","",IF(COUNTIF($B$6:$B$105,B8)>1,"模型重复",IF(OR(A8="",C8="",D8="",H8=""),"信息不完整","待系统验证"))) -> 待系统验证
A9: GPT-6 Sol | B9: gpt-6-sol | C9: OpenAI | D9: 文本 | E9: 自动 | F9: 后校验 | G9: 16384 | H9: 暂不发布 | I9: =IF(B9="","",IF(COUNTIF($B$6:$B$105,B9)>1,"模型重复",IF(OR(A9="",C9="",D9="",H9=""),"信息不完整","待系统验证"))) -> 待系统验证
A10: GPT-6 Luna | B10: gpt-6-luna | C10: OpenAI | D10: 文本 | E10: 自动 | F10: 后校验 | G10: 8192 | H10: 暂不发布 | I10: =IF(B10="","",IF(COUNTIF($B$6:$B$105,B10)>1,"模型重复",IF(OR(A10="",C10="",D10="",H10=""),"信息不完整","待系统验证"))) -> 待系统验证
A11: GPT-6.1 Terra | B11: gpt-6.1-terra | C11: OpenAI | D11: 文本、图片 | E11: 自动 | F11: 后校验 | G11: 8192 | H11: 暂不发布 | I11: =IF(B11="","",IF(COUNTIF($B$6:$B$105,B11)>1,"模型重复",IF(OR(A11="",C11="",D11="",H11=""),"信息不完整","待系统验证"))) -> 待系统验证
A12: GPT-5.5 | B12: gpt-5.5 | C12: OpenAI | D12: 文本 | E12: 自动 | F12: 后校验 | G12: 8192 | H12: 暂不发布 | I12: =IF(B12="","",IF(COUNTIF($B$6:$B$105,B12)>1,"模型重复",IF(OR(A12="",C12="",D12="",H12=""),"信息不完整","待系统验证"))) -> 待系统验证
A13: Claude Fable 5.1 | B13: claude-fable-5-1 | C13: Anthropic | D13: 文本、图片 | E13: 自动 | F13: 后校验 | G13: 16384 | H13: 暂不发布 | I13: =IF(B13="","",IF(COUNTIF($B$6:$B$105,B13)>1,"模型重复",IF(OR(A13="",C13="",D13="",H13=""),"信息不完整","待系统验证"))) -> 待系统验证
A14: Claude Opus 5.5 | B14: claude-opus-5-5 | C14: Anthropic | D14: 文本、图片 | E14: 自动 | F14: 后校验 | G14: 16384 | H14: 暂不发布 | I14: =IF(B14="","",IF(COUNTIF($B$6:$B$105,B14)>1,"模型重复",IF(OR(A14="",C14="",D14="",H14=""),"信息不完整","待系统验证"))) -> 待系统验证
A15: Claude Sonnet 5.5 | B15: claude-sonnet-5-5 | C15: Anthropic | D15: 文本、图片 | E15: 自动 | F15: 后校验 | G15: 16384 | H15: 暂不发布 | I15: =IF(B15="","",IF(COUNTIF($B$6:$B$105,B15)>1,"模型重复",IF(OR(A15="",C15="",D15="",H15=""),"信息不完整","待系统验证"))) -> 待系统验证
A16: Claude Haiku 5.5 | B16: claude-haiku-5-5 | C16: Anthropic | D16: 文本、图片 | E16: 自动 | F16: 后校验 | G16: 8192 | H16: 暂不发布 | I16: =IF(B16="","",IF(COUNTIF($B$6:$B$105,B16)>1,"模型重复",IF(OR(A16="",C16="",D16="",H16=""),"信息不完整","待系统验证"))) -> 待系统验证
A17: Gemini 3.8 Flash | B17: gemini-3.8-flash | C17: Gemini | D17: 文本、图片 | E17: 自动 | F17: 后校验 | G17: 16384 | H17: 暂不发布 | I17: =IF(B17="","",IF(COUNTIF($B$6:$B$105,B17)>1,"模型重复",IF(OR(A17="",C17="",D17="",H17=""),"信息不完整","待系统验证"))) -> 待系统验证
... A64: GLM 5.3 Flash | B64: glm-5.3-flash | C64: GLM | D64: 文本 | E64: 自动 | F64: 后校验 | G64: 8192 | H64: 暂不发布 | I64: =IF(B64="","",IF(COUNTIF($B$6:$B$105,B64)>1,"模型重复",IF(OR(A64="",C64="",D64="",H64=""),"信息不完整","待系统验证"))) -> 待系统验证
I65: =IF(B65="","",IF(COUNTIF($B$6:$B$105,B65)>1,"模型重复",IF(OR(A65="",C65="",D65="",H65=""),"信息不完整","待系统验证")))
I66: =IF(B66="","",IF(COUNTIF($B$6:$B$105,B66)>1,"模型重复",IF(OR(A66="",C66="",D66="",H66=""),"信息不完整","待系统验证")))
I67: =IF(B67="","",IF(COUNTIF($B$6:$B$105,B67)>1,"模型重复",IF(OR(A67="",C67="",D67="",H67=""),"信息不完整","待系统验证")))
I68: =IF(B68="","",IF(COUNTIF($B$6:$B$105,B68)>1,"模型重复",IF(OR(A68="",C68="",D68="",H68=""),"信息不完整","待系统验证")))
I69: =IF(B69="","",IF(COUNTIF($B$6:$B$105,B69)>1,"模型重复",IF(OR(A69="",C69="",D69="",H69=""),"信息不完整","待系统验证")))
I70: =IF(B70="","",IF(COUNTIF($B$6:$B$105,B70)>1,"模型重复",IF(OR(A70="",C70="",D70="",H70=""),"信息不完整","待系统验证")))
I71: =IF(B71="","",IF(COUNTIF($B$6:$B$105,B71)>1,"模型重复",IF(OR(A71="",C71="",D71="",H71=""),"信息不完整","待系统验证")))
I72: =IF(B72="","",IF(COUNTIF($B$6:$B$105,B72)>1,"模型重复",IF(OR(A72="",C72="",D72="",H72=""),"信息不完整","待系统验证")))
I73: =IF(B73="","",IF(COUNTIF($B$6:$B$105,B73)>1,"模型重复",IF(OR(A73="",C73="",D73="",H73=""),"信息不完整","待系统验证")))
I74: =IF(B74="","",IF(COUNTIF($B$6:$B$105,B74)>1,"模型重复",IF(OR(A74="",C74="",D74="",H74=""),"信息不完整","待系统验证")))
I75: =IF(B75="","",IF(COUNTIF($B$6:$B$105,B75)>1,"模型重复",IF(OR(A75="",C75="",D75="",H75=""),"信息不完整","待系统验证")))
I76: =IF(B76="","",IF(COUNTIF($B$6:$B$105,B76)>1,"模型重复",IF(OR(A76="",C76="",D76="",H76=""),"信息不完整","待系统验证")))
... I105: =IF(B105="","",IF(COUNTIF($B$6:$B$105,B105)>1,"模型重复",IF(OR(A105="",C105="",D105="",H105=""),"信息不完整","待系统验证")))

Sheet 缓存设置
A1: 缓存设置
A2: 同一模型在不同渠道分别配置缓存；示例值不是渠道验证结果。
A3: 浅黄色为可编辑项。4096 Token 是上游参考门槛，不代表 AIHubMix 已验证或当前系统已支持。
A5: 对外模型名 | B5: 渠道名称 | C5: 缓存机制 | D5: 默认策略 | E5: 可选强制 | F5: 计划门槛 Token | G5: 资源有效期 分钟 | H5: 自动准备失败时 | I5: 启用意向 | J5: 说明 | K5: 本地检查
A6: gemini-3.6-flash | B6: AIHubMix Gemini | C6: 显式资源 | D6: 自动 | E6: 否 | H6: 原文无缓存继续 | I6: 停用 | J6: 创建门槛、复用及用量须按此渠道实测 | K6: =IF(A6="","",IF(COUNTIFS('渠道优先级'!$A$6:$A$105,A6,'渠道优先级'!$C$6:$C$105,B6)=0,"渠道未登记",IF(OR(C6="",D6="",E6="",H6="",I6=""),"信息不完整",IF(COUNTIFS($A$6:$A$105,A6,$B$6:$B$105,B6)>1,"缓存配置重复",IF(AND(C6="隐式前缀",G6<>""),"隐式缓存无需有效期",IF(AND(D6="强制",E6="否"),"强制选项冲突","待系统验证")))))) -> 待系统验证
A7: gemini-3.6-flash | B7: Google 官方（规划） | C7: 显式资源 | D7: 自动 | E7: 否 | H7: 原文无缓存继续 | I7: 停用 | J7: 备用渠道示例；后端尚未接入 | K7: =IF(A7="","",IF(COUNTIFS('渠道优先级'!$A$6:$A$105,A7,'渠道优先级'!$C$6:$C$105,B7)=0,"渠道未登记",IF(OR(C7="",D7="",E7="",H7="",I7=""),"信息不完整",IF(COUNTIFS($A$6:$A$105,A7,$B$6:$B$105,B7)>1,"缓存配置重复",IF(AND(C7="隐式前缀",G7<>""),"隐式缓存无需有效期",IF(AND(D7="强制",E7="否"),"强制选项冲突","待系统验证")))))) -> 待系统验证
A8: gemini-4-argon | B8: AIHubMix Gemini | C8: 隐式前缀 | D8: 自动 | E8: 否 | F8: 4096 | H8: 不适用 | I8: 停用 | J8: 4096 为上游参考值；渠道与投影待验证 | K8: =IF(A8="","",IF(COUNTIFS('渠道优先级'!$A$6:$A$105,A8,'渠道优先级'!$C$6:$C$105,B8)=0,"渠道未登记",IF(OR(C8="",D8="",E8="",H8="",I8=""),"信息不完整",IF(COUNTIFS($A$6:$A$105,A8,$B$6:$B$105,B8)>1,"缓存配置重复",IF(AND(C8="隐式前缀",G8<>""),"隐式缓存无需有效期",IF(AND(D8="强制",E8="否"),"强制选项冲突","待系统验证")))))) -> 待系统验证
A9: gemini-4-argon | B9: Google 官方（规划） | C9: 隐式前缀 | D9: 自动 | E9: 否 | F9: 4096 | H9: 不适用 | I9: 停用 | J9: 备用渠道示例；后端尚未接入 | K9: =IF(A9="","",IF(COUNTIFS('渠道优先级'!$A$6:$A$105,A9,'渠道优先级'!$C$6:$C$105,B9)=0,"渠道未登记",IF(OR(C9="",D9="",E9="",H9="",I9=""),"信息不完整",IF(COUNTIFS($A$6:$A$105,A9,$B$6:$B$105,B9)>1,"缓存配置重复",IF(AND(C9="隐式前缀",G9<>""),"隐式缓存无需有效期",IF(AND(D9="强制",E9="否"),"强制选项冲突","待系统验证")))))) -> 待系统验证
A10: gpt-6-astra | B10: OpenAI 官方（规划） | C10: 不使用 | D10: 关闭 | E10: 否 | H10: 不适用 | I10: 停用 | J10: Relay 主动缓存默认关闭；确认真实供应能力后再按 V5 配置。 | K10: =IF(A10="","",IF(COUNTIFS('渠道优先级'!$A$6:$A$105,A10,'渠道优先级'!$C$6:$C$105,B10)=0,"渠道未登记",IF(OR(C10="",D10="",E10="",H10="",I10=""),"信息不完整",IF(COUNTIFS($A$6:$A$105,A10,$B$6:$B$105,B10)>1,"缓存配置重复",IF(AND(C10="隐式前缀",G10<>""),"隐式缓存无需有效期",IF(AND(D10="强制",E10="否"),"强制选项冲突","待系统验证")))))) -> 待系统验证
A11: gpt-6-sol | B11: OpenAI 官方（规划） | C11: 不使用 | D11: 关闭 | E11: 否 | H11: 不适用 | I11: 停用 | J11: Relay 主动缓存默认关闭；确认真实供应能力后再按 V5 配置。 | K11: =IF(A11="","",IF(COUNTIFS('渠道优先级'!$A$6:$A$105,A11,'渠道优先级'!$C$6:$C$105,B11)=0,"渠道未登记",IF(OR(C11="",D11="",E11="",H11="",I11=""),"信息不完整",IF(COUNTIFS($A$6:$A$105,A11,$B$6:$B$105,B11)>1,"缓存配置重复",IF(AND(C11="隐式前缀",G11<>""),"隐式缓存无需有效期",IF(AND(D11="强制",E11="否"),"强制选项冲突","待系统验证")))))) -> 待系统验证
A12: gpt-6-luna | B12: OpenAI 官方（规划） | C12: 不使用 | D12: 关闭 | E12: 否 | H12: 不适用 | I12: 停用 | J12: Relay 主动缓存默认关闭；确认真实供应能力后再按 V5 配置。 | K12: =IF(A12="","",IF(COUNTIFS('渠道优先级'!$A$6:$A$105,A12,'渠道优先级'!$C$6:$C$105,B12)=0,"渠道未登记",IF(OR(C12="",D12="",E12="",H12="",I12=""),"信息不完整",IF(COUNTIFS($A$6:$A$105,A12,$B$6:$B$105,B12)>1,"缓存配置重复",IF(AND(C12="隐式前缀",G12<>""),"隐式缓存无需有效期",IF(AND(D12="强制",E12="否"),"强制选项冲突","待系统验证")))))) -> 待系统验证
A13: gpt-6.1-terra | B13: OpenAI 官方（规划） | C13: 不使用 | D13: 关闭 | E13: 否 | H13: 不适用 | I13: 停用 | J13: Relay 主动缓存默认关闭；确认真实供应能力后再按 V5 配置。 | K13: =IF(A13="","",IF(COUNTIFS('渠道优先级'!$A$6:$A$105,A13,'渠道优先级'!$C$6:$C$105,B13)=0,"渠道未登记",IF(OR(C13="",D13="",E13="",H13="",I13=""),"信息不完整",IF(COUNTIFS($A$6:$A$105,A13,$B$6:$B$105,B13)>1,"缓存配置重复",IF(AND(C13="隐式前缀",G13<>""),"隐式缓存无需有效期",IF(AND(D13="强制",E13="否"),"强制选项冲突","待系统验证")))))) -> 待系统验证
A14: gpt-5.5 | B14: OpenAI 官方（规划） | C14: 不使用 | D14: 关闭 | E14: 否 | H14: 不适用 | I14: 停用 | J14: Relay 主动缓存默认关闭；确认真实供应能力后再按 V5 配置。 | K14: =IF(A14="","",IF(COUNTIFS('渠道优先级'!$A$6:$A$105,A14,'渠道优先级'!$C$6:$C$105,B14)=0,"渠道未登记",IF(OR(C14="",D14="",E14="",H14="",I14=""),"信息不完整",IF(COUNTIFS($A$6:$A$105,A14,$B$6:$B$105,B14)>1,"缓存配置重复",IF(AND(C14="隐式前缀",G14<>""),"隐式缓存无需有效期",IF(AND(D14="强制",E14="否"),"强制选项冲突","待系统验证")))))) -> 待系统验证
A15: claude-fable-5-1 | B15: Anthropic 官方（规划） | C15: 不使用 | D15: 关闭 | E15: 否 | H15: 不适用 | I15: 停用 | J15: Relay 主动缓存默认关闭；确认真实供应能力后再按 V5 配置。 | K15: =IF(A15="","",IF(COUNTIFS('渠道优先级'!$A$6:$A$105,A15,'渠道优先级'!$C$6:$C$105,B15)=0,"渠道未登记",IF(OR(C15="",D15="",E15="",H15="",I15=""),"信息不完整",IF(COUNTIFS($A$6:$A$105,A15,$B$6:$B$105,B15)>1,"缓存配置重复",IF(AND(C15="隐式前缀",G15<>""),"隐式缓存无需有效期",IF(AND(D15="强制",E15="否"),"强制选项冲突","待系统验证")))))) -> 待系统验证
A16: claude-opus-5-5 | B16: Anthropic 官方（规划） | C16: 不使用 | D16: 关闭 | E16: 否 | H16: 不适用 | I16: 停用 | J16: Relay 主动缓存默认关闭；确认真实供应能力后再按 V5 配置。 | K16: =IF(A16="","",IF(COUNTIFS('渠道优先级'!$A$6:$A$105,A16,'渠道优先级'!$C$6:$C$105,B16)=0,"渠道未登记",IF(OR(C16="",D16="",E16="",H16="",I16=""),"信息不完整",IF(COUNTIFS($A$6:$A$105,A16,$B$6:$B$105,B16)>1,"缓存配置重复",IF(AND(C16="隐式前缀",G16<>""),"隐式缓存无需有效期",IF(AND(D16="强制",E16="否"),"强制选项冲突","待系统验证")))))) -> 待系统验证
A17: claude-sonnet-5-5 | B17: Anthropic 官方（规划） | C17: 不使用 | D17: 关闭 | E17: 否 | H17: 不适用 | I17: 停用 | J17: Relay 主动缓存默认关闭；确认真实供应能力后再按 V5 配置。 | K17: =IF(A17="","",IF(COUNTIFS('渠道优先级'!$A$6:$A$105,A17,'渠道优先级'!$C$6:$C$105,B17)=0,"渠道未登记",IF(OR(C17="",D17="",E17="",H17="",I17=""),"信息不完整",IF(COUNTIFS($A$6:$A$105,A17,$B$6:$B$105,B17)>1,"缓存配置重复",IF(AND(C17="隐式前缀",G17<>""),"隐式缓存无需有效期",IF(AND(D17="强制",E17="否"),"强制选项冲突","待系统验证")))))) -> 待系统验证
A18: claude-haiku-5-5 | B18: Anthropic 官方（规划） | C18: 不使用 | D18: 关闭 | E18: 否 | H18: 不适用 | I18: 停用 | J18: Relay 主动缓存默认关闭；确认真实供应能力后再按 V5 配置。 | K18: =IF(A18="","",IF(COUNTIFS('渠道优先级'!$A$6:$A$105,A18,'渠道优先级'!$C$6:$C$105,B18)=0,"渠道未登记",IF(OR(C18="",D18="",E18="",H18="",I18=""),"信息不完整",IF(COUNTIFS($A$6:$A$105,A18,$B$6:$B$105,B18)>1,"缓存配置重复",IF(AND(C18="隐式前缀",G18<>""),"隐式缓存无需有效期",IF(AND(D18="强制",E18="否"),"强制选项冲突","待系统验证")))))) -> 待系统验证
A19: gemini-3.8-flash | B19: Google 官方（规划） | C19: 不使用 | D19: 关闭 | E19: 否 | H19: 不适用 | I19: 停用 | J19: Relay 主动缓存默认关闭；确认真实供应能力后再按 V5 配置。 | K19: =IF(A19="","",IF(COUNTIFS('渠道优先级'!$A$6:$A$105,A19,'渠道优先级'!$C$6:$C$105,B19)=0,"渠道未登记",IF(OR(C19="",D19="",E19="",H19="",I19=""),"信息不完整",IF(COUNTIFS($A$6:$A$105,A19,$B$6:$B$105,B19)>1,"缓存配置重复",IF(AND(C19="隐式前缀",G19<>""),"隐式缓存无需有效期",IF(AND(D19="强制",E19="否"),"强制选项冲突","待系统验证")))))) -> 待系统验证
A20: gemini-3.5-flash-lite | B20: Google 官方（规划） | C20: 不使用 | D20: 关闭 | E20: 否 | H20: 不适用 | I20: 停用 | J20: Relay 主动缓存默认关闭；确认真实供应能力后再按 V5 配置。 | K20: =IF(A20="","",IF(COUNTIFS('渠道优先级'!$A$6:$A$105,A20,'渠道优先级'!$C$6:$C$105,B20)=0,"渠道未登记",IF(OR(C20="",D20="",E20="",H20="",I20=""),"信息不完整",IF(COUNTIFS($A$6:$A$105,A20,$B$6:$B$105,B20)>1,"缓存配置重复",IF(AND(C20="隐式前缀",G20<>""),"隐式缓存无需有效期",IF(AND(D20="强制",E20="否"),"强制选项冲突","待系统验证")))))) -> 待系统验证
A21: gemini-3.1-flash-lite | B21: Google 官方（规划） | C21: 不使用 | D21: 关闭 | E21: 否 | H21: 不适用 | I21: 停用 | J21: Relay 主动缓存默认关闭；确认真实供应能力后再按 V5 配置。 | K21: =IF(A21="","",IF(COUNTIFS('渠道优先级'!$A$6:$A$105,A21,'渠道优先级'!$C$6:$C$105,B21)=0,"渠道未登记",IF(OR(C21="",D21="",E21="",H21="",I21=""),"信息不完整",IF(COUNTIFS($A$6:$A$105,A21,$B$6:$B$105,B21)>1,"缓存配置重复",IF(AND(C21="隐式前缀",G21<>""),"隐式缓存无需有效期",IF(AND(D21="强制",E21="否"),"强制选项冲突","待系统验证")))))) -> 待系统验证
... A66: glm-5.3-flash | B66: 智谱官方（规划） | C66: 不使用 | D66: 关闭 | E66: 否 | H66: 不适用 | I66: 停用 | J66: 未经渠道级缓存认证，Relay 主动缓存关闭。不是对上游透明缓存的承诺。 | K66: =IF(A66="","",IF(COUNTIFS('渠道优先级'!$A$6:$A$105,A66,'渠道优先级'!$C$6:$C$105,B66)=0,"渠道未登记",IF(OR(C66="",D66="",E66="",H66="",I66=""),"信息不完整",IF(COUNTIFS($A$6:$A$105,A66,$B$6:$B$105,B66)>1,"缓存配置重复",IF(AND(C66="隐式前缀",G66<>""),"隐式缓存无需有效期",IF(AND(D66="强制",E66="否"),"强制选项冲突","待系统验证")))))) -> 待系统验证
K67: =IF(A67="","",IF(COUNTIFS('渠道优先级'!$A$6:$A$105,A67,'渠道优先级'!$C$6:$C$105,B67)=0,"渠道未登记",IF(OR(C67="",D67="",E67="",H67="",I67=""),"信息不完整",IF(COUNTIFS($A$6:$A$105,A67,$B$6:$B$105,B67)>1,"缓存配置重复",IF(AND(C67="隐式前缀",G67<>""),"隐式缓存无需有效期",IF(AND(D67="强制",E67="否"),"强制选项冲突","待系统验证"))))))
K68: =IF(A68="","",IF(COUNTIFS('渠道优先级'!$A$6:$A$105,A68,'渠道优先级'!$C$6:$C$105,B68)=0,"渠道未登记",IF(OR(C68="",D68="",E68="",H68="",I68=""),"信息不完整",IF(COUNTIFS($A$6:$A$105,A68,$B$6:$B$105,B68)>1,"缓存配置重复",IF(AND(C68="隐式前缀",G68<>""),"隐式缓存无需有效期",IF(AND(D68="强制",E68="否"),"强制选项冲突","待系统验证"))))))
K69: =IF(A69="","",IF(COUNTIFS('渠道优先级'!$A$6:$A$105,A69,'渠道优先级'!$C$6:$C$105,B69)=0,"渠道未登记",IF(OR(C69="",D69="",E69="",H69="",I69=""),"信息不完整",IF(COUNTIFS($A$6:$A$105,A69,$B$6:$B$105,B69)>1,"缓存配置重复",IF(AND(C69="隐式前缀",G69<>""),"隐式缓存无需有效期",IF(AND(D69="强制",E69="否"),"强制选项冲突","待系统验证"))))))
K70: =IF(A70="","",IF(COUNTIFS('渠道优先级'!$A$6:$A$105,A70,'渠道优先级'!$C$6:$C$105,B70)=0,"渠道未登记",IF(OR(C70="",D70="",E70="",H70="",I70=""),"信息不完整",IF(COUNTIFS($A$6:$A$105,A70,$B$6:$B$105,B70)>1,"缓存配置重复",IF(AND(C70="隐式前缀",G70<>""),"隐式缓存无需有效期",IF(AND(D70="强制",E70="否"),"强制选项冲突","待系统验证"))))))
K71: =IF(A71="","",IF(COUNTIFS('渠道优先级'!$A$6:$A$105,A71,'渠道优先级'!$C$6:$C$105,B71)=0,"渠道未登记",IF(OR(C71="",D71="",E71="",H71="",I71=""),"信息不完整",IF(COUNTIFS($A$6:$A$105,A71,$B$6:$B$105,B71)>1,"缓存配置重复",IF(AND(C71="隐式前缀",G71<>""),"隐式缓存无需有效期",IF(AND(D71="强制",E71="否"),"强制选项冲突","待系统验证"))))))
K72: =IF(A72="","",IF(COUNTIFS('渠道优先级'!$A$6:$A$105,A72,'渠道优先级'!$C$6:$C$105,B72)=0,"渠道未登记",IF(OR(C72="",D72="",E72="",H72="",I72=""),"信息不完整",IF(COUNTIFS($A$6:$A$105,A72,$B$6:$B$105,B72)>1,"缓存配置重复",IF(AND(C72="隐式前缀",G72<>""),"隐式缓存无需有效期",IF(AND(D72="强制",E72="否"),"强制选项冲突","待系统验证"))))))
K73: =IF(A73="","",IF(COUNTIFS('渠道优先级'!$A$6:$A$105,A73,'渠道优先级'!$C$6:$C$105,B73)=0,"渠道未登记",IF(OR(C73="",D73="",E73="",H73="",I73=""),"信息不完整",IF(COUNTIFS($A$6:$A$105,A73,$B$6:$B$105,B73)>1,"缓存配置重复",IF(AND(C73="隐式前缀",G73<>""),"隐式缓存无需有效期",IF(AND(D73="强制",E73="否"),"强制选项冲突","待系统验证"))))))
K74: =IF(A74="","",IF(COUNTIFS('渠道优先级'!$A$6:$A$105,A74,'渠道优先级'!$C$6:$C$105,B74)=0,"渠道未登记",IF(OR(C74="",D74="",E74="",H74="",I74=""),"信息不完整",IF(COUNTIFS($A$6:$A$105,A74,$B$6:$B$105,B74)>1,"缓存配置重复",IF(AND(C74="隐式前缀",G74<>""),"隐式缓存无需有效期",IF(AND(D74="强制",E74="否"),"强制选项冲突","待系统验证"))))))
K75: =IF(A75="","",IF(COUNTIFS('渠道优先级'!$A$6:$A$105,A75,'渠道优先级'!$C$6:$C$105,B75)=0,"渠道未登记",IF(OR(C75="",D75="",E75="",H75="",I75=""),"信息不完整",IF(COUNTIFS($A$6:$A$105,A75,$B$6:$B$105,B75)>1,"缓存配置重复",IF(AND(C75="隐式前缀",G75<>""),"隐式缓存无需有效期",IF(AND(D75="强制",E75="否"),"强制选项冲突","待系统验证"))))))
K76: =IF(A76="","",IF(COUNTIFS('渠道优先级'!$A$6:$A$105,A76,'渠道优先级'!$C$6:$C$105,B76)=0,"渠道未登记",IF(OR(C76="",D76="",E76="",H76="",I76=""),"信息不完整",IF(COUNTIFS($A$6:$A$105,A76,$B$6:$B$105,B76)>1,"缓存配置重复",IF(AND(C76="隐式前缀",G76<>""),"隐式缓存无需有效期",IF(AND(D76="强制",E76="否"),"强制选项冲突","待系统验证"))))))
K77: =IF(A77="","",IF(COUNTIFS('渠道优先级'!$A$6:$A$105,A77,'渠道优先级'!$C$6:$C$105,B77)=0,"渠道未登记",IF(OR(C77="",D77="",E77="",H77="",I77=""),"信息不完整",IF(COUNTIFS($A$6:$A$105,A77,$B$6:$B$105,B77)>1,"缓存配置重复",IF(AND(C77="隐式前缀",G77<>""),"隐式缓存无需有效期",IF(AND(D77="强制",E77="否"),"强制选项冲突","待系统验证"))))))
K78: =IF(A78="","",IF(COUNTIFS('渠道优先级'!$A$6:$A$105,A78,'渠道优先级'!$C$6:$C$105,B78)=0,"渠道未登记",IF(OR(C78="",D78="",E78="",H78="",I78=""),"信息不完整",IF(COUNTIFS($A$6:$A$105,A78,$B$6:$B$105,B78)>1,"缓存配置重复",IF(AND(C78="隐式前缀",G78<>""),"隐式缓存无需有效期",IF(AND(D78="强制",E78="否"),"强制选项冲突","待系统验证"))))))
... K105: =IF(A105="","",IF(COUNTIFS('渠道优先级'!$A$6:$A$105,A105,'渠道优先级'!$C$6:$C$105,B105)=0,"渠道未登记",IF(OR(C105="",D105="",E105="",H105="",I105=""),"信息不完整",IF(COUNTIFS($A$6:$A$105,A105,$B$6:$B$105,B105)>1,"缓存配置重复",IF(AND(C105="隐式前缀",G105<>""),"隐式缓存无需有效期",IF(AND(D105="强制",E105="否"),"强制选项冲突","待系统验证"))))))

Sheet 填写说明
A1: 填写说明
A2: 配置规则与范围
A5: 事项 | B5: 规则
A6: 模型 | B6: “模型清单”中对外模型名唯一；新增模型先登记，再配渠道和缓存。
A7: 渠道 | B7: “渠道优先级”每行对应一个模型、一个环境、一个渠道；渠道名称须由后端登记。
A8: 顺位 | B8: 同一模型、同一环境下按 1、2、3 选择；重复顺位或渠道配置拒绝发布。
A9: 新会话 | B9: 只在新会话建立时依次筛选启用且合格的渠道；按“不可用时”决定是否尝试下一顺位。
A10: 已绑定会话 | B10: 会话建立后保持原渠道与缓存上下文；运行中错误不会自动跨渠道重试。
A11: 缓存 | B11: 同一模型各渠道分别填写。强制缓存只在机制经渠道验证且系统已实现时允许。
A12: 缓存失败 | B12: 自动模式可按同一上下文无缓存继续；强制模式失败，不偷偷降级。
A13: 隐式缓存关闭 | B13: “关闭”只关闭 Relay 主动缓存行为，不能关闭提供方可能自动执行的透明缓存。
A14: 发布 | B14: 所有示例处于停用草案。填写单元格不直接生效；系统仍须完成验证、审批与发布。
A15: 内部信息 | B15: 证据编号、连接编号、凭证、接口投影、哈希与版本号由后端管理，不进入用户表。
A18: 参考资料
A19: Gemini 缓存说明 | B19: https://ai.google.dev/gemini-api/docs/generate-content/caching
A20: Gemini 4 Argon | B20: https://ai.google.dev/gemini-api/docs/models/gemini-4-argon
A21: 目录扩充声明 | B21: 扩充的是待认证的候选模型目录，不是部署可用模型清单；所有新增行默认暂不发布、渠道停用、缓存停用。
A22: 目标输出上限 | B22: 新增行的 8192 / 16384 Token 是建议的业务目标上限，不代表厂商实际输出上限。未提供能力证据时发布会被拒绝。
A23: 模型别名与渠道 | B23: 有些 upstream ID 属于聚合渠道，有些 latest 为可变别名，Llama 项是仓库 ID。启用前必须冻结准确的渠道、账号、区域、端点、型号和证据。
A24: 缓存安全性 | B24: 新增行的“不使用/关闭/停用”是 Relay 控制缓存设置，不等于供应商透明缓存必定关闭。不能通过表格推定缓存机制/TTL。
A26: 资料来源（官方/托管平台） | B26: 模型目录与模型 ID 校验入口；访问日期 2026-10-28。上线前仍须验证账号、区域和具体端点。
A27: OpenAI | B27: https://developers.openai.com/api/docs/models/all
A28: Anthropic | B28: https://platform.claude.com/docs/en/models/overview
A29: Gemini | B29: https://ai.google.dev/gemini-api/docs/models
A30: Qwen | B30: https://www.alibabacloud.com/help/en/model-studio/text-generation-model
A31: DeepSeek | B31: https://api-docs.deepseek.com/updates/
... A47: 官方与聚合别名 | B47: 用户截图及补充型号；必须以对应上游平台 model-list / 实测确认为准
A49: 本轮补漏 · 型号 ID 与渠道别名核验（2026-10-28）
A50: 对外模型 ID | B50: 核验分类与发布限制
A51: gemini-3.1-pro-preview | B51: 官方预览模型；Preview 型号；需按账号、区域和渠道确认仍可调用 参考：https://ai.google.dev/gemini-api/docs/models
A52: gemini-3.1-pro-preview-search | B52: 用户截图所示聚合路由别名；Google 官方目录未列出此带 -search 后缀的独立型号；是否绑定搜索工具须单独验收 参考：https://ai.google.dev/gemini-api/docs/models
A53: gemini-3.5-flash-lite-free | B53: 用户截图所示聚合免费路由别名；Google 官方型号为 gemini-3.5-flash-lite；-free 仅按截图登记，不能推断免费额度 参考：https://ai.google.dev/gemini-api/docs/models
A54: grok-4.5 | B54: 官方模型 ID；具体提供范围、协议和账号可用性待认证 参考：https://docs.x.ai/developers/pricing
A55: grok-4.6 | B55: 官方模型 ID；具体提供范围、协议和账号可用性待认证 参考：https://docs.x.ai/developers/pricing
A56: kimi-k3 | B56: Moonshot 模型；各渠道 ID 可能不同；Moonshot/聚合渠道实际 API 型号和参数须逐渠道冻结 参考：https://huggingface.co/moonshotai/Kimi-K3
A57: kimi-k2.7-code | B57: Moonshot 编码模型；官方权重名称与 API ID 区别；编码模型；推理参数与可用接入协议单独验证 参考：https://huggingface.co/moonshotai/Kimi-K2.7-Code
A58: claude-sonnet-5 | B58: 官方 API 模型 ID；不是 Claude Sonnet 5.5；两者作为独立型号冻结 参考：https://platform.claude.com/docs/en/models/overview
A59: coding-glm-5.3-free | B59: 用户提供的聚合免费路由别名；不等于 Z.AI 官方 glm-5.3；免费/限流/代码接口需渠道认证 参考：https://zcode.z.ai/cn/docs/configuration
A60: xiaomi-mimo-v2.6-pro-free | B60: 用户提供的聚合免费路由别名；小米官方 ID 为 mimo-v2.6-pro；-free 是独立聚合渠道路由声明 参考：https://mimo.mi.com/docs/en-US/quick-start/model
A61: gpt-6.1-sol | B61: 额外补漏：官方新版模型 ID；不能用 gpt-6-sol 的旧档位或协议兼容假设代替新版认证 参考：https://developers.openai.com/api/docs/models/all
...
